Workbook

Sheet Sales
A1: OrderID | B1: Order date | C1: Order Month | D1: CustomerID | E1: ProductID | F1: Quantity | G1: SalesAmount | H1: Category | I1: Country | J1: SIGNUPDATE | K1: SIGNUPMONTH | L1: Column1
A2: ORD0001 | B2: 45302 | C2: =TEXT(B2, "mmm") -> Jan | D2: CUST115 | E2: PROD020 | F2: 5 | G2: 2098.25 | H2: =VLOOKUP(Sales!E:E, Table2[#All], 3,FALSE) -> Sports | I2: =VLOOKUP(D:D,Table3[#All], 4, FALSE) -> Canada | J2: =VLOOKUP(D:D,Table3[#All], 5, FALSE) -> 45210 | K2: =TEXT(Table1[[#This Row],[SIGNUPDATE]], "mmm, yy") -> Oct, 23 | L2: =IFERROR(VLOOKUP(D:D,Customer_info!A:A, 1, FALSE), "Not found") -> CUST115
A3: ORD0002 | B3: 45312 | C3: =TEXT(B3, "mmm") -> Jan | D3: CUST077 | E3: PROD032 | F3: 5 | G3: 199.35 | H3: =VLOOKUP(Sales!E:E, Table2[#All], 3,FALSE) -> Sports | I3: =VLOOKUP(D:D,Table3[#All], 4, FALSE) -> India | J3: =VLOOKUP(D:D,Table3[#All], 5, FALSE) -> 44985 | K3: =TEXT(Table1[[#This Row],[SIGNUPDATE]], "mmm, yy") -> Feb, 23 | L3: =IFERROR(VLOOKUP(D:D,Customer_info!A:A, 1, FALSE), "Not found") -> CUST077
A4: ORD0003 | B4: 45460 | C4: =TEXT(B4, "mmm") -> Jun | D4: CUST091 | E4: PROD017 | F4: 4 | G4: 946.76 | H4: =VLOOKUP(Sales!E:E, Table2[#All], 3,FALSE) -> Home | I4: =VLOOKUP(D:D,Table3[#All], 4, FALSE) -> Canada | J4: =VLOOKUP(D:D,Table3[#All], 5, FALSE) -> 44927 | K4: =TEXT(Table1[[#This Row],[SIGNUPDATE]], "mmm, yy") -> Jan, 23 | L4: =IFERROR(VLOOKUP(D:D,Customer_info!A:A, 1, FALSE), "Not found") -> CUST091
A5: ORD0004 | B5: 45436 | C5: =TEXT(B5, "mmm") -> May | D5: CUST097 | E5: PROD006 | F5: 5 | G5: 1972.3 | H5: =VLOOKUP(Sales!E:E, Table2[#All], 3,FALSE) -> Clothing | I5: =VLOOKUP(D:D,Table3[#All], 4, FALSE) -> Canada | J5: =VLOOKUP(D:D,Table3[#All], 5, FALSE) -> 44967 | K5: =TEXT(Table1[[#This Row],[SIGNUPDATE]], "mmm, yy") -> Feb, 23 | L5: =IFERROR(VLOOKUP(D:D,Customer_info!A:A, 1, FALSE), "Not found") -> CUST097
A6: ORD0005 | B6: 45372 | C6: =TEXT(B6, "mmm") -> Mar | D6: CUST018 | E6: PROD039 | F6: 5 | G6: 1039.25 | H6: =VLOOKUP(Sales!E:E, Table2[#All], 3,FALSE) -> Clothing | I6: =VLOOKUP(D:D,Table3[#All], 4, FALSE) -> United States | J6: =VLOOKUP(D:D,Table3[#All], 5, FALSE) -> 45101 | K6: =TEXT(Table1[[#This Row],[SIGNUPDATE]], "mmm, yy") -> Jun, 23 | L6: =IFERROR(VLOOKUP(D:D,Customer_info!A:A, 1, FALSE), "Not found") -> CUST018
A7: ORD0006 | B7: 45344 | C7: =TEXT(B7, "mmm") -> Feb | D7: CUST038 | E7: PROD007 | F7: 3 | G7: 309.9 | H7: =VLOOKUP(Sales!E:E, Table2[#All], 3,FALSE) -> Beauty | I7: =VLOOKUP(D:D,Table3[#All], 4, FALSE) -> US | J7: =VLOOKUP(D:D,Table3[#All], 5, FALSE) -> 45010 | K7: =TEXT(Table1[[#This Row],[SIGNUPDATE]], "mmm, yy") -> Mar, 23 | L7: =IFERROR(VLOOKUP(D:D,Customer_info!A:A, 1, FALSE), "Not found") -> CUST038
A8: ORD0007 | B8: 45353 | C8: =TEXT(B8, "mmm") -> Mar | D8: CUST060 | E8: PROD027 | F8: 3 | G8: 449.31 | H8: =VLOOKUP(Sales!E:E, Table2[#All], 3,FALSE) -> Beauty | I8: =VLOOKUP(D:D,Table3[#All], 4, FALSE) -> United Kingdom | J8: =VLOOKUP(D:D,Table3[#All], 5, FALSE) -> 45053 | K8: =TEXT(Table1[[#This Row],[SIGNUPDATE]], "mmm, yy") -> May, 23 | L8: =IFERROR(VLOOKUP(D:D,Customer_info!A:A, 1, FALSE), "Not found") -> CUST060
A9: ORD0008 | B9: 45393 | C9: =TEXT(B9, "mmm") -> Apr | D9: CUST115 | E9: PROD024 | F9: 3 | G9: 1356.6 | H9: =VLOOKUP(Sales!E:E, Table2[#All], 3,FALSE) -> Beauty | I9: =VLOOKUP(D:D,Table3[#All], 4, FALSE) -> Canada | J9: =VLOOKUP(D:D,Table3[#All], 5, FALSE) -> 45210 | K9: =TEXT(Table1[[#This Row],[SIGNUPDATE]], "mmm, yy") -> Oct, 23 | L9: =IFERROR(VLOOKUP(D:D,Customer_info!A:A, 1, FALSE), "Not found") -> CUST115
A10: ORD0009 | B10: 45463 | C10: =TEXT(B10, "mmm") -> Jun | D10: CUST006 | E10: PROD024 | F10: 2 | G10: 904.4 | H10: =VLOOKUP(Sales!E:E, Table2[#All], 3,FALSE) -> Beauty | I10: =VLOOKUP(D:D,Table3[#All], 4, FALSE) -> UK | J10: =VLOOKUP(D:D,Table3[#All], 5, FALSE) -> 45229 | K10: =TEXT(Table1[[#This Row],[SIGNUPDATE]], "mmm, yy") -> Oct, 23 | L10: =IFERROR(VLOOKUP(D:D,Customer_info!A:A, 1, FALSE), "Not found") -> CUST006
A11: ORD0010 | B11: 45409 | C11: =TEXT(B11, "mmm") -> Apr | D11: CUST021 | E11: PROD006 | F11: 3 | G11: 1183.38 | H11: =VLOOKUP(Sales!E:E, Table2[#All], 3,FALSE) -> Clothing | I11: =VLOOKUP(D:D,Table3[#All], 4, FALSE) -> UK | J11: =VLOOKUP(D:D,Table3[#All], 5, FALSE) -> 44974 | K11: =TEXT(Table1[[#This Row],[SIGNUPDATE]], "mmm, yy") -> Feb, 23 | L11: =IFERROR(VLOOKUP(D:D,Customer_info!A:A, 1, FALSE), "Not found") -> CUST021
A12: ORD0011 | B12: 45310 | C12: =TEXT(B12, "mmm") -> Jan | D12: CUST041 | E12: PROD005 | F12: 3 | G12: 877.02 | H12: =VLOOKUP(Sales!E:E, Table2[#All], 3,FALSE) -> Sports | I12: =VLOOKUP(D:D,Table3[#All], 4, FALSE) -> US | J12: =VLOOKUP(D:D,Table3[#All], 5, FALSE) -> 45286 | K12: =TEXT(Table1[[#This Row],[SIGNUPDATE]], "mmm, yy") -> Dec, 23 | L12: =IFERROR(VLOOKUP(D:D,Customer_info!A:A, 1, FALSE), "Not found") -> CUST041
A13: ORD0012 | B13: 45409 | C13: =TEXT(B13, "mmm") -> Apr | D13: CUST110 | E13: PROD028 | F13: 1 | G13: 334.32 | H13: =VLOOKUP(Sales!E:E, Table2[#All], 3,FALSE) -> Sports | I13: =VLOOKUP(D:D,Table3[#All], 4, FALSE) -> US | J13: =VLOOKUP(D:D,Table3[#All], 5, FALSE) -> 45151 | K13: =TEXT(Table1[[#This Row],[SIGNUPDATE]], "mmm, yy") -> Aug, 23 | L13: =IFERROR(VLOOKUP(D:D,Customer_info!A:A, 1, FALSE), "Not found") -> CUST110
... A361: ORD0360 | B361: 45295 | C361: =TEXT(B361, "mmm") -> Jan | D361: CUST103 | E361: PROD024 | F361: 5 | G361: 2261 | H361: =VLOOKUP(Sales!E:E, Table2[#All], 3,FALSE) -> Beauty | I361: =VLOOKUP(D:D,Table3[#All], 4, FALSE) -> US | J361: =VLOOKUP(D:D,Table3[#All], 5, FALSE) -> 45197 | K361: =TEXT(Table1[[#This Row],[SIGNUPDATE]], "mmm, yy") -> Sep, 23 | L361: =IFERROR(VLOOKUP(D:D,Customer_info!A:A, 1, FALSE), "Not found") -> CUST103

Sheet Products
A1: ProductID | B1: ProductName | C1: Category | D1: UnitPrice
A2: PROD001 | B2: Product_1 | C2: Electronics | D2: 431.22
A3: PROD002 | B3: Product_2 | C3: Electronics | D3: 261.94
A4: PROD003 | B4: Product_3 | C4: Home | D4: 337.8
A5: PROD004 | B5: Product_4 | C5: Clothing | D5: 274.22
A6: PROD005 | B6: Product_5 | C6: Sports | D6: 292.34
A7: PROD006 | B7: Product_6 | C7: Clothing | D7: 394.46
A8: PROD007 | B8: Product_7 | C8: Beauty | D8: 103.3
A9: PROD008 | B9: Product_8 | C9: Electronics | D9: 332.9
A10: PROD009 | B10: Product_9 | C10: Home | D10: 217.55
A11: PROD010 | B11: Product_10 | C11: Beauty | D11: 433.28
A12: PROD011 | B12: Product_11 | C12: Electronics | D12: 339.95
A13: PROD012 | B13: Product_12 | C13: Electronics | D13: 39.7
... A41: PROD040 | B41: Product_40 | C41: Sports | D41: 130.65

Sheet Customer_info
A1: CustomerID | B1: CustomerName | C1: Email | D1: Country | E1: SignupDate
A2: CUST001 | B2: Customer_1 | C2: customer1@email.com | D2: India | E2: 44984
A3: CUST002 | B3: Customer_2 | C3: customer2@email.com | D3: UK | E3: 45067
A4: CUST003 | B4: Customer_3 | C4: customer3@email.com | D4: United Kingdom | E4: 45041
A5: CUST004 | B5: Customer_4 | C5: customer4@email.com | D5: United Kingdom | E5: 44979
A6: CUST005 | B6: Customer_5 | C6: customer5@email.com | D6: India | E6: 45206
A7: CUST006 | B7: Customer_6 | C7: customer6@email.com | D7: UK | E7: 45229
A8: CUST007 | B8: Customer_7 | C8: customer7@email.com | D8: United States | E8: 44943
A9: CUST008 | B9: Customer_8 | C9: customer8@email.com | D9: UK | E9: 44974
A10: CUST009 | B10: Customer_9 | C10: customer9@email.com | D10: United Kingdom | E10: 45046
A11: CUST010 | B11: Customer_10 | C11: customer10@email.com | D11: Canada | E11: 45235
A12: CUST011 | B12: Customer_11 | C12: customer11@email.com | D12: UK | E12: 45214
A13: CUST012 | B13: Customer_12 | C13: customer12@email.com | D13: United Kingdom | E13: 45259
... A17: CUST016 | B17: Customer_16 | C17: customer16@email.com | D17: US | E17: 44930
A18: CUST017 | B18: Customer_17 | C18: customer17@email.com | D18: United Kingdom | E18: 45284 | H18: `
A19: CUST018 | B19: Customer_18 | C19: customer18@email.com | D19: United States | E19: 45101
A20: CUST019 | B20: Customer_19 | C20: customer19@email.com | D20: US | E20: 45006
A21: CUST020 | B21: Customer_20 | C21: customer20@email.com | D21: United Kingdom | E21: 45099
A22: CUST021 | B22: Customer_21 | C22: customer21@email.com | D22: UK | E22: 44974
A23: CUST022 | B23: Customer_22 | C23: customer22@email.com | D23: United States | E23: 44976
A24: CUST023 | B24: Customer_23 | C24: customer23@email.com | D24: US | E24: 45103
A25: CUST024 | B25: Customer_24 | C25: customer24@email.com | D25: Canada | E25: 45062
A26: CUST025 | B26: Customer_25 | C26: customer25@email.com | D26: UK | E26: 45162
A27: CUST026 | B27: Customer_26 | C27: customer26@email.com | D27: Canada | E27: 44990
A28: CUST027 | B28: Customer_27 | C28: customer27@email.com | D28: United States | E28: 44967
A29: CUST028 | B29: Customer_28 | C29: customer28@email.com | D29: Canada | E29: 45077
A30: CUST029 | B30: Customer_29 | C30: customer29@email.com | D30: India | E30: 45243
... A121: CUST120 | B121: Customer_120 | C121: customer120@email.com | D121: United Kingdom | E121: 44961

Sheet metrics calculation
A1: total revenue | D1: monthly revenue
A2: =SUM(Sales!G:G) -> 249314.65 | D2: Row Labels | E2: Sum of SalesAmount | G2: revenue growth rate | I2: repeat purchase rate
D3: Jan | E3: 38121.72 | F3: Jan | I3: =E14/A13 -> 0.825
A4: number of orders | D4: Feb | E4: 36272.57 | F4: Feb | G4: =(GETPIVOTDATA("SalesAmount",$D$2,"Order Month","Feb") -GETPIVOTDATA("SalesAmount",$D$2,"Order Month","Jan")) /GETPIVOTDATA("SalesAmount",$D$2,"Order Month","Jan") -> -0.048506468
A5: =COUNTA(Sales!A:A)-1 -> 360 | D5: Mar | E5: 52091.57 | F5: Mar | G5: =(GETPIVOTDATA("SalesAmount",$D$2,"Order Month","Mar") -GETPIVOTDATA("SalesAmount",$D$2,"Order Month","Feb"))/GETPIVOTDATA("SalesAmount",$D$2,"Order Month","Feb") -> 0.43611467 | I5: new customers per month
D6: Apr | E6: 37290.87 | F6: Apr | G6: =(GETPIVOTDATA("SalesAmount",$D$2,"Order Month","Apr")-GETPIVOTDATA("SalesAmount",$D$2,"Order Month","Mar"))/GETPIVOTDATA("SalesAmount",$D$2,"Order Month","Mar") -> -0.28412851
A7: AOV | D7: May | E7: 33711.56 | F7: May | G7: =(GETPIVOTDATA("SalesAmount",$D$2,"Order Month","May")-GETPIVOTDATA("SalesAmount",$D$2,"Order Month","Apr"))/GETPIVOTDATA("SalesAmount",$D$2,"Order Month","Apr") -> -0.095983548
A8: =A2/A5 -> 692.54069 | D8: Jun | E8: 51826.36 | F8: Jun | G8: =(GETPIVOTDATA("SalesAmount",$D$2,"Order Month","Jun")-GETPIVOTDATA("SalesAmount",$D$2,"Order Month","May"))/GETPIVOTDATA("SalesAmount",$D$2,"Order Month","May") -> 0.53734683
D9: Grand Total | E9: 249314.65
A12: total customers | C12: customers with >1 order = 99
A13: =COUNTA(Customer_info!A:A)-1 -> 120 | C13: Row Labels | D13: Count of OrderID | E13: repeat customers | G13: revenue by category | J13: revenue by country
C14: CUST001 | D14: 6 | E14: 99 | G14: Row Labels | H14: Sum of SalesAmount | J14: Row Labels | K14: Sum of SalesAmount
C15: CUST002 | D15: 6 | G15: Beauty | H15: 49960.63 | J15: Canada | K15: 57774.68
C16: CUST003 | D16: 3 | G16: Clothing | H16: 37792.22 | J16: India | K16: 51405.48
C17: CUST005 | D17: 8 | G17: Electronics | H17: 74267.19 | J17: UK | K17: 45344.27
C18: CUST006 | D18: 6 | G18: Home | H18: 42451.15 | J18: United Kingdom | K18: 41535.32
C19: CUST008 | D19: 4 | G19: Sports | H19: 44843.46 | J19: United States | K19: 22096.23
C20: CUST009 | D20: 2 | G20: Grand Total | H20: 249314.65 | J20: US | K20: 31158.67
C21: CUST010 | D21: 2 | J21: Grand Total | K21: 249314.65
C22: CUST012 | D22: 3
C23: CUST014 | D23: 5
C24: CUST015 | D24: 4 | G24: signupmonth | H24: Count of CustomerID
C25: CUST016 | D25: 4 | G25: Oct, 23 | H25: 45
C26: CUST017 | D26: 3 | G26: Feb, 23 | H26: 48 | J26: Row Labels | K26: Sum of SalesAmount | L26: Count of OrderID
C27: CUST018 | D27: 3 | G27: Jan, 23 | H27: 25 | J27: CUST005 | K27: 8064.34 | L27: 8
C28: CUST020 | D28: 2 | G28: Jun, 23 | H28: 21 | J28: CUST097 | K28: 6805.47 | L28: 5
C29: CUST021 | D29: 2 | G29: Mar, 23 | H29: 29 | J29: CUST115 | K29: 6150.95 | L29: 4
C30: CUST022 | D30: 4 | G30: May, 23 | H30: 49 | J30: CUST091 | K30: 5991.77 | L30: 6
C31: CUST023 | D31: 5 | G31: Dec, 23 | H31: 23 | J31: CUST083 | K31: 5603.24 | L31: 7
C32: CUST024 | D32: 2 | G32: Aug, 23 | H32: 32 | J32: CUST030 | K32: 5286.42 | L32: 6
C33: CUST025 | D33: 3 | G33: Nov, 23 | H33: 22 | J33: CUST048 | K33: 5217.3 | L33: 5
C34: CUST026 | D34: 2 | G34: Apr, 23 | H34: 28 | J34: CUST059 | K34: 5179.45 | L34: 10
C35: CUST027 | D35: 2 | G35: Sep, 23 | H35: 21 | J35: CUST042 | K35: 4854.1 | L35: 3
C36: CUST029 | D36: 4 | G36: Jul, 23 | H36: 14 | J36: CUST067 | K36: 4606.64 | L36: 6
C37: CUST030 | D37: 6 | G37: Jan, 24 | H37: 3 | J37: CUST015 | K37: 4221.48 | L37: 4
C38: CUST031 | D38: 3 | G38: Grand Total | H38: 360 | J38: CUST018 | K38: 4025.22 | L38: 3 | P38: lifespan
C39: CUST032 | D39: 2 | J39: CUST094 | K39: 3990.59 | L39: 4 | P39: Row Labels | Q39: Max of Order date | R39: Min of Order date | S39: Count of OrderID | T39: lifespan | W39: frequency | X39: clv
C40: CUST034 | D40: 2 | J40: CUST099 | K40: 3885.64 | L40: 3 | P40: CUST001 | Q40: 45472 | R40: 45305 | S40: 6 | T40: =Q39:Q154-R39:R154 -> 167 | U40: =AVERAGE(T40:T154) -> 75.8 | W40: =IF(T40<>0,GETPIVOTDATA("Count of OrderID",$P$39,"CustomerID","CUST001")/T40,0) -> 0.035928144 | X40: =A8 * W40 *T40 -> 4155.2442 | Z40: =AVERAGE(W40:W154) -> 0.12021058
C41: CUST035 | D41: 4 | J41: CUST069 | K41: 3854.09 | L41: 6 | P41: CUST002 | Q41: 45444 | R41: 45298 | S41: 6 | T41: =Q40:Q155-R40:R155 -> 146 | W41: =IF(T41<>0,GETPIVOTDATA("Count of OrderID",$P$39,"CustomerID","CUST001")/T41,0) -> 0.04109589 | X41: =A9 * W41 *T41 -> 0
C42: CUST036 | D42: 2 | J42: CUST022 | K42: 3808.51 | L42: 4 | P42: CUST003 | Q42: 45404 | R42: 45330 | S42: 3 | T42: =Q41:Q156-R41:R156 -> 74 | W42: =IF(T42<>0,GETPIVOTDATA("Count of OrderID",$P$39,"CustomerID","CUST001")/T42,0) -> 0.081081081 | X42: =A10 * W42 *T42 -> 0
...

Sheet Dashboard
H10: Revenue Growth Trend
H11: Jan
H12: Feb | I12: -0.05
H13: Mar | I13: 0.44
H14: Apr | I14: -0.28
H15: May | I15: -0.1
H16: Jun | I16: 0.54
